<?xml version="1.0" ?>
<!-- TODO: Add GPS sensor -->
<robot name="navi_car">
  <material name="black">
    <color rgba="0.2 0.2 0.2 1"/>
  </material>
  <material name="blue">
    <color rgba="0.1 0.1 0.5 1"/>
  </material>

  <!-- base_link relates to its projection on the ground by this offset:
    <origin xyz="0 0 0.31" rpy="0 0 0"/>
  -->


  <link name="base_link">
    <visual>
      <geometry>
        <cylinder length="0.05" radius="0.05"/>
      </geometry>
      <material name="red"/>
      <origin xyz="0 0 0.025" rpy="0 0 0"/>
    </visual>
  </link>

  <link name="nav_base"/>

  <joint name="nav_base_joint" type="fixed">
    <parent link="base_link"/>
    <child link="nav_base"/>
    <origin xyz="0 0 0" rpy="0 0 0"/>
  </joint>

  <link name="axis">
    <visual>
      <geometry>
        <cylinder length="0.3" radius="0.2"/>
      </geometry>
      <material name="black"/>
      <origin xyz="0 0 0.15" rpy="0 0 0"/>
    </visual>
    <collision>
      <geometry>
        <box size="0.25 0.4 0.6"/>
      </geometry>
      <origin xyz="0 0 0.15" rpy="0 0 0"/>
    </collision>
    <inertial>
      <!-- TODO: Get or calculate inertia values -->
      <origin xyz="0 0 0.013" rpy="0 0 0"/>
      <mass value="0.25"/>
      <inertia ixx="0.0003350833" ixy="0" ixz="0"
        iyy="0.000560417" iyz="0"
        izz="0.000478833"/>
    </inertial>
  </link>

  <link name="lidar_front">
    <visual>
      <geometry>
        <cylinder length="0.076" radius="0.0401"/>
      </geometry>
      <material name="blue"/>
    </visual>
    <collision>
      <geometry>
        <cylinder length="0.076" radius="0.0401"/>
      </geometry>
    </collision>
  </link>

  <joint name="axis_joint" type="continuous">
    <parent link="base_link"/>
    <child link="axis"/>
    <origin rpy="0 0 0" xyz="0 0 0"/>
  </joint>
  
  <joint name="lidar_front_joint" type="fixed">
    <parent link="axis"/>
    <child link="lidar_front"/>
    <origin xyz="0.14965 0 0.49516" rpy="0.45 0 1.570796"/>
  </joint>

</robot>

